Workbook
Name _1월: '[1]소정근로일(2019)'!$AE$5:$AE$26
Name _2월: '[1]소정근로일(2019)'!$AI$5:$AI$26
Name _8월: '[1]소정근로일(2019)'!$S$5:$S$26
Name _9월: '[1]소정근로일(2019)'!$W$5:$W$26
Name _linkedcell: #REF!
Name _linkedcell: #REF!
Name _linkedcell: #REF!
Name p_1월: '[1]소정근로일(2018)'!$AE$5:$AE$26
Name p_2월: '[1]소정근로일(2018)'!$AI$5:$AI$26
Name p_8월: '[1]소정근로일(2018)'!$S$5:$S$26
Name p_9월: '[1]소정근로일(2018)'!$W$5:$W$26
Name p_공휴일_등: '[1]소정근로일(2018)'!$AR$2:$AR$26
Name p_요일: '[1]소정근로일(2018)'!$AS$2:$AS$26
Name Pay_Title: OFFSET([2]급여내역!$G$5,0,0,1,COUNTA([2]급여내역!$5:$5))
Name 가나나나나나나나나나: #REF!
Name 가나나나나나나나나나: #REF!
Name 가나나나나나나나나나: #REF!
Name 가나나나나나나나나나: #REF!
Name 건강: [3]건강보험료!$A:$O
Name 계: #REF!
Name 계: '[4]2018복무'!#REF!
Name 계: #REF!
Name 고용: [3]고용보험료!$A:$O
Name 공휴일_등: '[1]소정근로일(2019)'!$AR$2:$AR$26
Name 국민: [3]국민연금!$A:$O
Name 근무상황: #REF!
Name 근무상황: '[4]2018복무'!$C:$C
Name 근무상황: #REF!
Name 근속: [3]근속가산금!$A:$N
Name 근속변경일: [5]개발전용!#REF!
Name 근속변경일: [5]개발전용!#REF!
Name 근속변경일: [5]개발전용!#REF!
Name 급별: [6]기초!$C$3:$C$12
Name 급식: [3]급식비!$A:$N
Name 기본: [3]기본급!$A:$N
Name 기술: [3]기술정보수당!$A:$N
Name 기타: [3]기타공제!$A:$N
Name ㅁㅇㄹ: [5]개발전용!#REF!
Name ㅁㅇㄹ: [5]개발전용!#REF!
Name ㅁㅇㄹ: [5]개발전용!#REF!
Name 맞춤: [3]맞춤형복지비!$A:$N
Name 명절: [3]명절휴가비!$A:$N
Name 보육: [3]보육수당!$A:$N
Name 분: #REF!
Name 분: '[4]2018복무'!$I:$I
Name 분: #REF!
Name 사용연차: [1]연차수당내역!#REF!
Name 사용연차: [1]연차수당내역!#REF!
Name 사용연차: [1]연차수당내역!#REF!
Name 사용연차: [1]연차수당내역!#REF!
Name 설립별: [6]기초!$E$3:$E$5
Name 성명: '[1]기초자료(통상임금)'!$D$7:$D$26
Name 성명: '[4]2018복무'!$B:$B
Name 성명: '[1]기초자료(통상임금)'!$D$7:$D$26
Name 성명: #REF!
Name 성별: [6]Sheet3!$H$6:$H$7
Name 소득: [3]소득세!$A:$N
Name 소속: [6]Sheet3!$I$2:$I$13
Name 소정근로일: '[1]소정근로일(2019)'!$AP$7:$AP$26
Name 시: #REF!

Sheet 연차유급휴가 일수 산출내역
D1: 학년도 연차유급휴가 일수 산출 내역
AG2: 15
B3: 순 | C3: 학교명 | D3: 직 | E3: 성 명 | F3: 생년월일 | G3: 근무형태 | H3: 최 초 채용일 | I3: 발생일자 | M3: 일자기준 | O3: 경 력 산 정 및 발 생 일 수 산 정 | U3: 발생일수 (①+②) 한도25일 | V3: 기준시간 (시간) | W3: 소정 근로시간 | X3: 사용가능 연차일수 계산 | AF3: 최종연차 발생일수 | AG3: 연차일수
I4: 발생일자 기준 현경력기간 계산 | O4: 발생일기준 현경력 (연단위) | P4: 전임경력 (연단위) | Q4: 경력당 연차 발생일수 | X4: 2025 | AA4: 학년도 | AE4: 산정일수
I5: ㉠발생일자 기준 | K5: ㉡재직기간 제외휴직 총기간 | M5: ㉢현경력 (㉠-㉡) | Q5: 전임경력 가산일수 | R5: ⓐ연차발생일수(경력제외) | S5: ⓑ현경력가산 | T5: 현경력 ⓐ+ⓑ | X5: 상시근로자 소정근로일수 | Y5: 출근의무일수 (a) | Z5: 결근으로 보는일수 (b) | AA5: 개인소정근로일수 (a)-(b) | AB5: 출근율80% 달성여부 | AD5: 만근 개월수 | AF5: =K3 -> 0 | AG5: 일 | AH5: 시 | AI5: 분
B6: =ROW()-5 -> 1 | G6: 상시근무자 | I6: =IF(DATEDIF(H6,$K$3,"Y")<10,"0"&DATEDIF(H6,$K$3,"Y"),DATEDIF(H6,$K$3,"Y"))&"년"&IF(DATEDIF(H6,$K$3,"YM")<10,"0"&DATEDIF(H6,$K$3,"YM"),DATEDIF(H6,$K$3,"YM"))&"월" -> 00년00월 | K6: 0 | L6: 0 | M6: =DATEDIF(EDATE(H6,K6*12+L6),$K$3,"y")&"년" & DATEDIF(EDATE(H6,K6*12+L6),$K$3,"ym")&"월" -> 0년0월 | O6: =IF(DATEDIF(EDATE(H6,K6*12+L6),$K$3,"y")=0,1,DATEDIF(EDATE(H6,K6*12+L6),$K$3,"y")) -> 1 | P6: 0 | Q6: =VLOOKUP(P6,참조!$N$3:$O$23,2,0) -> 0 | R6: =$AG$2 -> 15 | S6: =VLOOKUP(O6,참조!$A$3:$C$34,3,0) -> 0 | T6: =R6+S6 -> 15 | U6: =IF(Q6+T6>25,"25일",Q6+T6) -> 15 | V6: 8 | W6: =IF(V6=8,209,IF(V6=5,130,104)) -> 209 | X6: =달력!$AK$50 -> 243 | Z6: 0 | AA6: =Y6-Z6 -> 0 | AB6: =AA6/Y6*100 -> #DIV/0! | AC6: =IF(AB6>=80,"달성","미달성") -> #DIV/0! | AD6: 0 | AE6: =IF(G6="상시전일근무자",IF(AC6="미달성",AD6,ROUNDDOWN((Q6+R6+S6)*AA6/X6,1)),IF(AC6="미달성",AD6,ROUNDDOWN((Q6+R6)*AA6/X6,1)+S6)) -> #DIV/0! | AF6: =IF(AE6>=25,25,CEILING(AE6, 0.5)) -> #DIV/0! | AG6: =IFERROR(INT(AF6),"") | AH6: =IFERROR(IF(MOD(AF6,1)=0,0,IF(V6=8,4,2)),"") | AI6: =IFERROR(IF(MOD(AF6,1)=0,0,IF(V6=8,0,IF(V6=5,30,0))),"")
B7: =ROW()-5 -> 2 | G7: 상시근무자 | I7: =IF(DATEDIF(H7,$K$3,"Y")<10,"0"&DATEDIF(H7,$K$3,"Y"),DATEDIF(H7,$K$3,"Y"))&"년"&IF(DATEDIF(H7,$K$3,"YM")<10,"0"&DATEDIF(H7,$K$3,"YM"),DATEDIF(H7,$K$3,"YM"))&"월" -> 00년00월 | K7: 0 | L7: 0 | M7: =DATEDIF(EDATE(H7,K7*12+L7),$K$3,"y")&"년" & DATEDIF(EDATE(H7,K7*12+L7),$K$3,"ym")&"월" -> 0년0월 | O7: =IF(DATEDIF(EDATE(H7,K7*12+L7),$K$3,"y")=0,1,DATEDIF(EDATE(H7,K7*12+L7),$K$3,"y")) -> 1 | P7: 0 | Q7: =VLOOKUP(P7,참조!$N$3:$O$23,2,0) -> 0 | R7: =$AG$2 -> 15 | S7: =VLOOKUP(O7,참조!$A$3:$C$34,3,0) -> 0 | T7: =R7+S7 -> 15 | U7: =IF(Q7+T7>25,"25일",Q7+T7) -> 15 | V7: 8 | W7: =IF(V7=8,209,IF(V7=5,130,104)) -> 209 | X7: =달력!$AK$50 -> 243 | Z7: 0 | AA7: =Y7-Z7 -> 0 | AB7: =AA7/Y7*100 -> #DIV/0! | AC7: =IF(AB7>=80,"달성","미달성") -> #DIV/0! | AD7: 0 | AE7: =IF(G7="상시전일근무자",IF(AC7="미달성",AD7,ROUNDDOWN((Q7+R7+S7)*AA7/X7,1)),IF(AC7="미달성",AD7,ROUNDDOWN((Q7+R7)*AA7/X7,1)+S7)) -> #DIV/0! | AF7: =IF(AE7>=25,25,CEILING(AE7, 0.5)) -> #DIV/0! | AG7: =IFERROR(INT(AF7),"") | AH7: =IFERROR(IF(MOD(AF7,1)=0,0,IF(V7=8,4,2)),"") | AI7: =IFERROR(IF(MOD(AF7,1)=0,0,IF(V7=8,0,IF(V7=5,30,0))),"")
B8: =ROW()-5 -> 3 | G8: 상시근무자 | I8: =IF(DATEDIF(H8,$K$3,"Y")<10,"0"&DATEDIF(H8,$K$3,"Y"),DATEDIF(H8,$K$3,"Y"))&"년"&IF(DATEDIF(H8,$K$3,"YM")<10,"0"&DATEDIF(H8,$K$3,"YM"),DATEDIF(H8,$K$3,"YM"))&"월" -> 00년00월 | K8: 0 | L8: 0 | M8: =DATEDIF(EDATE(H8,K8*12+L8),$K$3,"y")&"년" & DATEDIF(EDATE(H8,K8*12+L8),$K$3,"ym")&"월" -> 0년0월 | O8: =IF(DATEDIF(EDATE(H8,K8*12+L8),$K$3,"y")=0,1,DATEDIF(EDATE(H8,K8*12+L8),$K$3,"y")) -> 1 | P8: 0 | Q8: =VLOOKUP(P8,참조!$N$3:$O$23,2,0) -> 0 | R8: =$AG$2 -> 15 | S8: =VLOOKUP(O8,참조!$A$3:$C$34,3,0) -> 0 | T8: =R8+S8 -> 15 | U8: =IF(Q8+T8>25,"25일",Q8+T8) -> 15 | V8: 8 | W8: =IF(V8=8,209,IF(V8=5,130,104)) -> 209 | X8: =달력!$AK$50 -> 243 | Z8: 0 | AA8: =Y8-Z8 -> 0 | AB8: =AA8/Y8*100 -> #DIV/0! | AC8: =IF(AB8>=80,"달성","미달성") -> #DIV/0! | AD8: 0 | AE8: =IF(G8="상시전일근무자",IF(AC8="미달성",AD8,ROUNDDOWN((Q8+R8+S8)*AA8/X8,1)),IF(AC8="미달성",AD8,ROUNDDOWN((Q8+R8)*AA8/X8,1)+S8)) -> #DIV/0! | AF8: =IF(AE8>=25,25,CEILING(AE8, 0.5)) -> #DIV/0! | AG8: =IFERROR(INT(AF8),"") | AH8: =IFERROR(IF(MOD(AF8,1)=0,0,IF(V8=8,4,2)),"") | AI8: =IFERROR(IF(MOD(AF8,1)=0,0,IF(V8=8,0,IF(V8=5,30,0))),"")

Sheet 달력
C1: 학년도 달력 | G1: <<< 행,열 삽입, 삭제 금지 >>> | Z1: (학교용) | AI1: =DATE(B1,1,1) -> 1 | AJ1: =DATE(B1,12,IF(DAY(EOMONTH(B37,0))=31,31,DAY(AD37+1))) -> 366
AI2: =DATE(B1,3,1) -> 61 | AJ2: =DATE(B1+1,2,IF(DAY(EOMONTH(B43,0))=28,28,DAY(AD43+1))) -> 425
B3: 년. 월 | C3: [ 월별 공휴일(토,일, 양력공휴일) 자동 표시 ] | AI3: 토,일요일 | AJ3: 공휴일등 (토,일제외) | AK3: 계
B4: =DATE(B1,1,1) -> 1 | C4: =B4 -> 1 | D4: =C4+1 -> 2 | E4: =D4+1 -> 3 | F4: =E4+1 -> 4 | G4: =F4+1 -> 5 | H4: =G4+1 -> 6 | I4: =H4+1 -> 7 | J4: =I4+1 -> 8 | K4: =J4+1 -> 9 | ... AG4: =AF4+1 -> 31
C5: =TEXT(C4,"aaa") -> 일 | D5: =TEXT(D4,"aaa") -> 월 | E5: =TEXT(E4,"aaa") -> 화 | F5: =TEXT(F4,"aaa") -> 수 | G5: =TEXT(G4,"aaa") -> 목 | H5: =TEXT(H4,"aaa") -> 금 | I5: =TEXT(I4,"aaa") -> 토 | J5: =TEXT(J4,"aaa") -> 일 | ... AG5: =TEXT(AG4,"aaa") -> 화
C6: 신정 | F6: 토 | G6: 일 | M6: 토 | N6: 일 | T6: 토 | U6: 일 | AA6: 토 | AB6: 일 | AC6: 임시공휴일 | AD6: 설연휴 | AE6: 설날 | AF6: 설연휴 | AI6: =COUNTIF(C6:AG6,"토")+COUNTIF(C6:AG6,"일") -> 8 | AJ6: =COUNTA(C6:AG6)-AI6 -> 5 | AK6: =AI6+AJ6 -> 13
B7: =EOMONTH(B4,0)+1 -> 32 | C7: =B7 -> 32 | D7: =C7+1 -> 33 | E7: =D7+1 -> 34 | F7: =E7+1 -> 35 | G7: =F7+1 -> 36 | H7: =G7+1 -> 37 | I7: =H7+1 -> 38 | J7: =I7+1 -> 39 | K7: =J7+1 -> 40 | ... AE7: =AD7+1 -> 60
C8: =TEXT(C7,"aaa") -> 수 | D8: =TEXT(D7,"aaa") -> 목 | E8: =TEXT(E7,"aaa") -> 금 | F8: =TEXT(F7,"aaa") -> 토 | G8: =TEXT(G7,"aaa") -> 일 | H8: =TEXT(H7,"aaa") -> 월 | I8: =TEXT(I7,"aaa") -> 화 | J8: =TEXT(J7,"aaa") -> 수 | ... AE8: =TEXT(AE7,"aaa") -> 수
C9: 토 | D9: 일 | J9: 토 | K9: 일 | Q9: 토 | R9: 일 | X9: 토 | Y9: 일 | AI9: =COUNTIF(C9:AG9,"토")+COUNTIF(C9:AG9,"일") -> 8 | AJ9: =COUNTA(C9:AG9)-AI9 -> 0 | AK9: =AI9+AJ9 -> 8
B10: =DATE(B1,3,1) -> 61 | C10: =B10 -> 61 | D10: =C10+1 -> 62 | E10: =D10+1 -> 63 | F10: =E10+1 -> 64 | G10: =F10+1 -> 65 | H10: =G10+1 -> 66 | I10: =H10+1 -> 67 | J10: =I10+1 -> 68 | K10: =J10+1 -> 69 | ... AG10: =AF10+1 -> 91
C11: =TEXT(C10,"aaa") -> 목 | D11: =TEXT(D10,"aaa") -> 금 | E11: =TEXT(E10,"aaa") -> 토 | F11: =TEXT(F10,"aaa") -> 일 | G11: =TEXT(G10,"aaa") -> 월 | H11: =TEXT(H10,"aaa") -> 화 | I11: =TEXT(I10,"aaa") -> 수 | J11: =TEXT(J10,"aaa") -> 목 | ... AG11: =TEXT(AG10,"aaa") -> 토
C12: 삼일절 | D12: 일 | E12: 대체휴일 | J12: 토 | K12: 일 | Q12: 토 | R12: 일 | X12: 토 | Y12: 일 | AE12: 토 | AF12: 일 | AI12: =COUNTIF(C12:AG12,"토")+COUNTIF(C12:AG12,"일") -> 9 | AJ12: =COUNTA(C12:AG12)-AI12 -> 2 | AK12: =AI12+AJ12 -> 11
B13: =EOMONTH(B10,0)+1 -> 92 | C13: =B13 -> 92 | D13: =C13+1 -> 93 | E13: =D13+1 -> 94 | F13: =E13+1 -> 95 | G13: =F13+1 -> 96 | H13: =G13+1 -> 97 | I13: =H13+1 -> 98 | J13: =I13+1 -> 99 | K13: =J13+1 -> 100 | ... AF13: =AE13+1 -> 121
C14: =TEXT(C13,"aaa") -> 일 | D14: =TEXT(D13,"aaa") -> 월 | E14: =TEXT(E13,"aaa") -> 화 | F14: =TEXT(F13,"aaa") -> 수 | G14: =TEXT(G13,"aaa") -> 목 | H14: =TEXT(H13,"aaa") -> 금 | I14: =TEXT(I13,"aaa") -> 토 | J14: =TEXT(J13,"aaa") -> 일 | ... AF14: =TEXT(AF13,"aaa") -> 월
G15: 토 | H15: 일 | N15: 토 | O15: 일 | U15: 토 | V15: 일 | AB15: 토 | AC15: 일 | AI15: =COUNTIF(C15:AG15,"토")+COUNTIF(C15:AG15,"일") -> 8 | AJ15: =COUNTA(C15:AG15)-AI15 -> 0 | AK15: =AI15+AJ15 -> 8
B16: =EOMONTH(B13,0)+1 -> 122 | C16: =B16 -> 122 | D16: =C16+1 -> 123 | E16: =D16+1 -> 124 | F16: =E16+1 -> 125 | G16: =F16+1 -> 126 | H16: =G16+1 -> 127 | I16: =H16+1 -> 128 | J16: =I16+1 -> 129 | K16: =J16+1 -> 130 | ... AG16: =AF16+1 -> 152
C17: =TEXT(C16,"aaa") -> 화 | D17: =TEXT(D16,"aaa") -> 수 | E17: =TEXT(E16,"aaa") -> 목 | F17: =TEXT(F16,"aaa") -> 금 | G17: =TEXT(G16,"aaa") -> 토 | H17: =TEXT(H16,"aaa") -> 일 | I17: =TEXT(I16,"aaa") -> 월 | J17: =TEXT(J16,"aaa") -> 화 | ... AG17: =TEXT(AG16,"aaa") -> 목
C18: 근로자의날 | E18: 토 | F18: 일 | G18: 어린이날 | H18: 대체휴일 | L18: 토 | M18: 일 | S18: 토 | T18: 일 | Z18: 토 | AA18: 일 | AG18: 토 | AI18: =COUNTIF(C18:AG18,"토")+COUNTIF(C18:AG18,"일") -> 9 | AJ18: =COUNTA(C18:AG18)-AI18 -> 3 | AK18: =AI18+AJ18 -> 12
B19: =EOMONTH(B16,0)+1 -> 153 | C19: =B19 -> 153 | D19: =C19+1 -> 154 | E19: =D19+1 -> 155 | F19: =E19+1 -> 156 | G19: =F19+1 -> 157 | H19: =G19+1 -> 158 | I19: =H19+1 -> 159 | J19: =I19+1 -> 160 | K19: =J19+1 -> 161 | ... AF19: =AE19+1 -> 182
C20: =TEXT(C19,"aaa") -> 금 | D20: =TEXT(D19,"aaa") -> 토 | E20: =TEXT(E19,"aaa") -> 일 | F20: =TEXT(F19,"aaa") -> 월 | G20: =TEXT(G19,"aaa") -> 화 | H20: =TEXT(H19,"aaa") -> 수 | I20: =TEXT(I19,"aaa") -> 목 | J20: =TEXT(J19,"aaa") -> 금 | ... AF20: =TEXT(AF19,"aaa") -> 토
C21: 일 | E21: 대통령선거 | H21: 현충일 | I21: 토 | J21: 일 | P21: 토 | Q21: 일 | W21: 토 | X21: 일 | AD21: 토 | AE21: 일 | AI21: =COUNTIF(C21:AG21,"토")+COUNTIF(C21:AG21,"일") -> 9 | AJ21: =COUNTA(C21:AG21)-AI21 -> 2 | AK21: =AI21+AJ21 -> 11
B22: =EOMONTH(B19,0)+1 -> 183 | C22: =B22 -> 183 | D22: =C22+1 -> 184 | E22: =D22+1 -> 185 | F22: =E22+1 -> 186 | G22: =F22+1 -> 187 | H22: =G22+1 -> 188 | I22: =H22+1 -> 189 | J22: =I22+1 -> 190 | K22: =J22+1 -> 191 | ... AG22: =AF22+1 -> 213
C23: =TEXT(C22,"aaa") -> 일 | D23: =TEXT(D22,"aaa") -> 월 | E23: =TEXT(E22,"aaa") -> 화 | F23: =TEXT(F22,"aaa") -> 수 | G23: =TEXT(G22,"aaa") -> 목 | H23: =TEXT(H22,"aaa") -> 금 | I23: =TEXT(I22,"aaa") -> 토 | J23: =TEXT(J22,"aaa") -> 일 | ... AG23: =TEXT(AG22,"aaa") -> 화
G24: 토 | H24: 일 | N24: 토 | O24: 일 | U24: 토 | V24: 일 | AB24: 토 | AC24: 일 | AI24: =COUNTIF(C24:AG24,"토")+COUNTIF(C24:AG24,"일") -> 8 | AJ24: =COUNTA(C24:AG24)-AI24 -> 0 | AK24: =AI24+AJ24 -> 8
B25: =EOMONTH(B22,0)+1 -> 214 | C25: =B25 -> 214 | D25: =C25+1 -> 215 | E25: =D25+1 -> 216 | F25: =E25+1 -> 217 | G25: =F25+1 -> 218 | H25: =G25+1 -> 219 | I25: =H25+1 -> 220 | J25: =I25+1 -> 221 | K25: =J25+1 -> 222 | ... AG25: =AF25+1 -> 244
C26: =TEXT(C25,"aaa") -> 수 | D26: =TEXT(D25,"aaa") -> 목 | E26: =TEXT(E25,"aaa") -> 금 | F26: =TEXT(F25,"aaa") -> 토 | G26: =TEXT(G25,"aaa") -> 일 | H26: =TEXT(H25,"aaa") -> 월 | I26: =TEXT(I25,"aaa") -> 화 | J26: =TEXT(J25,"aaa") -> 수 | ... AG26: =TEXT(AG25,"aaa") -> 금
D27: 토 | E27: 일 | K27: 토 | L27: 일 | Q27: 광복절 | R27: 토 | S27: 일 | Y27: 토 | Z27: 일 | AF27: 토 | AG27: 일 | AI27: =COUNTIF(C27:AG27,"토")+COUNTIF(C27:AG27,"일") -> 10 | AJ27: =COUNTA(C27:AG27)-AI27 -> 1 | AK27: =AI27+AJ27 -> 11
B28: =EOMONTH(B25,0)+1 -> 245 | C28: =B28 -> 245 | D28: =C28+1 -> 246 | E28: =D28+1 -> 247 | F28: =E28+1 -> 248 | G28: =F28+1 -> 249 | H28: =G28+1 -> 250 | I28: =H28+1 -> 251 | J28: =I28+1 -> 252 | K28: =J28+1 -> 253 | ... AF28: =AE28+1 -> 274
C29: =TEXT(C28,"aaa") -> 토 | D29: =TEXT(D28,"aaa") -> 일 | E29: =TEXT(E28,"aaa") -> 월 | F29: =TEXT(F28,"aaa") -> 화 | G29: =TEXT(G28,"aaa") -> 수 | H29: =TEXT(H28,"aaa") -> 목 | I29: =TEXT(I28,"aaa") -> 금 | J29: =TEXT(J28,"aaa") -> 토 | ... AF29: =TEXT(AF28,"aaa") -> 일
H30: 토 | I30: 일 | O30: 토 | P30: 일 | V30: 토 | W30: 일 | AC30: 토 | AD30: 일 | AI30: =COUNTIF(C30:AG30,"토")+COUNTIF(C30:AG30,"일") -> 8 | AJ30: =COUNTA(C30:AG30)-AI30 -> 0 | AK30: =AI30+AJ30 -> 8
B31: =EOMONTH(B28,0)+1 -> 275 | C31: =B31 -> 275 | D31: =C31+1 -> 276 | E31: =D31+1 -> 277 | F31: =E31+1 -> 278 | G31: =F31+1 -> 279 | H31: =G31+1 -> 280 | I31: =H31+1 -> 281 | J31: =I31+1 -> 282 | K31: =J31+1 -> 283 | ... AG31: =AF31+1 -> 305
C32: =TEXT(C31,"aaa") -> 월 | D32: =TEXT(D31,"aaa") -> 화 | E32: =TEXT(E31,"aaa") -> 수 | F32: =TEXT(F31,"aaa") -> 목 | G32: =TEXT(G31,"aaa") -> 금 | H32: =TEXT(H31,"aaa") -> 토 | I32: =TEXT(I31,"aaa") -> 일 | J32: =TEXT(J31,"aaa") -> 월 | ... AG32: =TEXT(AG31,"aaa") -> 수
E33: 개천절 | F33: 토 | G33: 일 | H33: 추석 | I33: 추석연휴 | J33: 대체휴일 | K33: 한글날 | M33: 토 | N33: 일 | T33: 토 | U33: 일 | AA33: 토 | AB33: 일 | AI33: =COUNTIF(C33:AG33,"토")+COUNTIF(C33:AG33,"일") -> 8 | AJ33: =COUNTA(C33:AG33)-AI33 -> 5 | AK33: =AI33+AJ33 -> 13
B34: =EOMONTH(B31,0)+1 -> 306 | C34: =B34 -> 306 | D34: =C34+1 -> 307 | E34: =D34+1 -> 308 | F34: =E34+1 -> 309 | G34: =F34+1 -> 310 | H34: =G34+1 -> 311 | I34: =H34+1 -> 312 | J34: =I34+1 -> 313 | K34: =J34+1 -> 314 | ... AF34: =AE34+1 -> 335
C35: =TEXT(C34,"aaa") -> 목 | D35: =TEXT(D34,"aaa") -> 금 | E35: =TEXT(E34,"aaa") -> 토 | F35: =TEXT(F34,"aaa") -> 일 | G35: =TEXT(G34,"aaa") -> 월 | H35: =TEXT(H34,"aaa") -> 화 | I35: =TEXT(I34,"aaa") -> 수 | J35: =TEXT(J34,"aaa") -> 목 | ... AF35: =TEXT(AF34,"aaa") -> 금
C36: 토 | D36: 일 | J36: 토 | K36: 일 | Q36: 토 | R36: 일 | X36: 토 | Y36: 일 | AE36: 토 | AF36: 일 | AI36: =COUNTIF(C36:AG36,"토")+COUNTIF(C36:AG36,"일") -> 10 | AJ36: =COUNTA(C36:AG36)-AI36 -> 0 | AK36: =AI36+AJ36 -> 10
B37: =EOMONTH(B34,0)+1 -> 336 | C37: =B37 -> 336 | D37: =C37+1 -> 337 | E37: =D37+1 -> 338 | F37: =E37+1 -> 339 | G37: =F37+1 -> 340 | H37: =G37+1 -> 341 | I37: =H37+1 -> 342 | J37: =I37+1 -> 343 | K37: =J37+1 -> 344 | ... AG37: =AF37+1 -> 366
C38: =TEXT(C37,"aaa") -> 토 | D38: =TEXT(D37,"aaa") -> 일 | E38: =TEXT(E37,"aaa") -> 월 | F38: =TEXT(F37,"aaa") -> 화 | G38: =TEXT(G37,"aaa") -> 수 | H38: =TEXT(H37,"aaa") -> 목 | I38: =TEXT(I37,"aaa") -> 금 | J38: =TEXT(J37,"aaa") -> 토 | ... AG38: =TEXT(AG37,"aaa") -> 월
H39: 토 | I39: 일 | O39: 토 | P39: 일 | V39: 토 | W39: 일 | AA39: 성탄절 | AC39: 토 | AD39: 일 | AI39: =COUNTIF(C39:AG39,"토")+COUNTIF(C39:AG39,"일") -> 8 | AJ39: =COUNTA(C39:AG39)-AI39 -> 1 | AK39: =AI39+AJ39 -> 9
B40: =EOMONTH(B37,0)+1 -> 367 | C40: =B40 -> 367 | D40: =C40+1 -> 368 | E40: =D40+1 -> 369 | F40: =E40+1 -> 370 | G40: =F40+1 -> 371 | H40: =G40+1 -> 372 | I40: =H40+1 -> 373 | J40: =I40+1 -> 374 | K40: =J40+1 -> 375 | ... AG40: =AF40+1 -> 397
...

Sheet 직종표
A1: 교육공무직원 직종표
A3: 번호 | B3: 직 종 명 | C3: 직종 설명
A4: 1 | B4: 교무행정실무원 | C4: 교수학습자료 제작, 수집, 보관 등의 교무 업무 수행
A5: 2 | B5: 교무행정사 | C5: 교사의 교무·행정업무 지원
A6: 3 | B6: 전산실무원 | C6: 전산수업 지원 및 교육정보화 기기 유지 관리
A7: 4 | B7: 행정실무원(호봉제)
A8: 5 | B8: 행정실무원(월급제)
A9: 6 | B9: 초등돌봄전담사 | C9: 초등 돌봄교실 프로그램 운영
A10: 7 | B10: 특수교육실무원 | C10: 중증장애학생의 학교 교육활동지원
A11: 8 | B11: 영양사 | C11: 학교급식을 위한 전반적인 업무
A12: 9 | B12: 조리사 | C12: 학교급식 조리 및 배식(자격증 소지자)
A13: 10 | B13: 조리원 | C13: 학교급식 조리 및 배식(자격증 미소지자)
A14: 11 | B14: 시설관리원 | C14: 시설물 유지 관리
A15: 12 | B15: 과학실험실무원
A16: 13 | B16: 교육복지사
A17: 14 | B17: 치료사
A18: 15 | B18: 희망일자리(4)
A19: 16 | B19: 희망일자리(8)
A20: 17 | B20: 임상심리사
A21: 18 | B21: 방과후학교운영실무원
A22: 19 | B22: 학부모지원전문가
A23: 20 | B23: 시각장애교사지원실무사
A24: 21 | B24: 행정실무원
A25: 25 | B25: 전문상담사 | C25: 위기학생 상담 및 치유
B28: 근무형태
A29: 1 | B29: 상시전일근무자
A30: 2 | B30: 방학중비근무

Sheet 참조
K1: 전임 | N1: 전임
A2: 근속 년수 | B2: 연차 일수 | C2: 현경력가산 | H2: 근속 년수 | I2: 연차 일수 | K2: 전임 경력 | L2: 가산일수 | N2: 전임 경력 | O2: 가산일수
A3: 1 | B3: 15 | C3: 0 | H3: 1 | I3: 15 | K3: 2 | L3: 1 | N3: 0 | O3: 0
A4: 2 | B4: 15 | C4: 0 | H4: 2 | I4: 15 | K4: 4 | L4: 2 | N4: 1 | O4: 0
A5: 3 | B5: 16 | C5: 1 | H5: 3 | I5: 16 | K5: 6 | L5: 3 | N5: 2 | O5: 1
A6: 4 | B6: 16 | C6: 1 | H6: 4 | I6: 16 | K6: 8 | L6: 4 | N6: 3 | O6: 1
A7: 5 | B7: 17 | C7: 2 | H7: 5 | I7: 17 | K7: 10 | L7: 5 | N7: 4 | O7: 2
A8: 6 | B8: 17 | C8: 2 | H8: 6 | I8: 17 | K8: 12 | L8: 6 | N8: 5 | O8: 2
A9: 7 | B9: 18 | C9: 3 | H9: 7 | I9: 18 | K9: 14 | L9: 7 | N9: 6 | O9: 3
A10: 8 | B10: 18 | C10: 3 | H10: 8 | I10: 18 | K10: 16 | L10: 8 | N10: 7 | O10: 3
A11: 9 | B11: 19 | C11: 4 | H11: 9 | I11: 19 | K11: 18 | L11: 9 | N11: 8 | O11: 4
A12: 10 | B12: 19 | C12: 4 | H12: 10 | I12: 19 | K12: 20 | L12: 10 | N12: 9 | O12: 4
A13: 11 | B13: 20 | C13: 5 | H13: 11 | I13: 20 | N13: 10 | O13: 5
A14: 12 | B14: 20 | C14: 5 | H14: 12 | I14: 20 | N14: 11 | O14: 5
A15: 13 | B15: 21 | C15: 6 | H15: 13 | I15: 21 | N15: 12 | O15: 6
A16: 14 | B16: 21 | C16: 6 | H16: 14 | I16: 21 | N16: 13 | O16: 6
A17: 15 | B17: 22 | C17: 7 | H17: 15 | I17: 22 | N17: 14 | O17: 7
A18: 16 | B18: 22 | C18: 7 | H18: 16 | I18: 22 | N18: 15 | O18: 7
A19: 17 | B19: 23 | C19: 8 | H19: 17 | I19: 23 | N19: 16 | O19: 8
A20: 18 | B20: 23 | C20: 8 | H20: 18 | I20: 23 | N20: 17 | O20: 8
A21: 19 | B21: 24 | C21: 9 | H21: 19 | I21: 24 | N21: 18 | O21: 9
A22: 20 | B22: 24 | C22: 9 | H22: 20 | I22: 24 | N22: 19 | O22: 9
A23: 21 | B23: 25 | C23: 10 | H23: 21 | I23: 25 | N23: 20 | O23: 10
A24: 22 | B24: 25 | C24: 10 | H24: 22 | I24: 25
A25: 23 | B25: 25 | C25: 10 | H25: 23 | I25: 25
A26: 24 | B26: 25 | C26: 10 | H26: 24 | I26: 25
A27: 25 | B27: 25 | C27: 10 | H27: 25 | I27: 25
A28: 26 | B28: 25 | C28: 10 | H28: 26 | I28: 25
A29: 27 | B29: 25 | C29: 10 | H29: 27 | I29: 25
A30: 28 | B30: 25 | C30: 10 | H30: 28 | I30: 25
A31: 29 | B31: 25 | C31: 10
A32: 30 | B32: 25 | C32: 10
A33: 31 | B33: 25 | C33: 10
A34: 32 | B34: 25 | C34: 10

Sheet 근속수당
A2: 근속 년수 | B2: 연차 일수
A3: 1 | B3: 41000
A4: 2 | B4: =41000*A4 -> 82000
A5: 3 | B5: =41000*A5 -> 123000
A6: 4 | B6: =41000*A6 -> 164000
A7: 5 | B7: =41000*A7 -> 205000
A8: 6 | B8: =41000*A8 -> 246000
A9: 7 | B9: =41000*A9 -> 287000
A10: 8 | B10: =41000*A10 -> 328000
A11: 9 | B11: =41000*A11 -> 369000
A12: 10 | B12: =41000*A12 -> 410000
A13: 11 | B13: =41000*A13 -> 451000
A14: 12 | B14: =41000*A14 -> 492000
A15: 13 | B15: =41000*A15 -> 533000
... A29: 27 | B29: =41000*A29 -> 1107000
